2021-02-05 18:42:58,367 ERROR: Exception on /index/ [GET] [in /run/media/ine/1B6EC43665352BA7/yandex/web_info/flask/env/lib/python3.9/site-packages/flask/app.py:1891]
Traceback (most recent call last):
  File "/run/media/ine/1B6EC43665352BA7/yandex/web_info/flask/env/lib/python3.9/site-packages/flask/app.py", line 2447, in wsgi_app
    response = self.full_dispatch_request()
  File "/run/media/ine/1B6EC43665352BA7/yandex/web_info/flask/env/lib/python3.9/site-packages/flask/app.py", line 1952, in full_dispatch_request
    rv = self.handle_user_exception(e)
  File "/run/media/ine/1B6EC43665352BA7/yandex/web_info/flask/env/lib/python3.9/site-packages/flask/app.py", line 1821, in handle_user_exception
    reraise(exc_type, exc_value, tb)
  File "/run/media/ine/1B6EC43665352BA7/yandex/web_info/flask/env/lib/python3.9/site-packages/flask/_compat.py", line 39, in reraise
    raise value
  File "/run/media/ine/1B6EC43665352BA7/yandex/web_info/flask/env/lib/python3.9/site-packages/flask/app.py", line 1950, in full_dispatch_request
    rv = self.dispatch_request()
  File "/run/media/ine/1B6EC43665352BA7/yandex/web_info/flask/env/lib/python3.9/site-packages/flask/app.py", line 1936, in dispatch_request
    return self.view_functions[rule.endpoint](**req.view_args)
  File "/run/media/ine/1B6EC43665352BA7/yandex/web_info/flask/env/lib/python3.9/site-packages/flask_login/utils.py", line 272, in decorated_view
    return func(*args, **kwargs)
  File "/run/media/ine/1B6EC43665352BA7/yandex/web_info/flask/app/routes.py", line 32, in index
    return render_template('index.html', title="Home", posts=posts, form=form)
  File "/run/media/ine/1B6EC43665352BA7/yandex/web_info/flask/env/lib/python3.9/site-packages/flask/templating.py", line 137, in render_template
    return _render(
  File "/run/media/ine/1B6EC43665352BA7/yandex/web_info/flask/env/lib/python3.9/site-packages/flask/templating.py", line 120, in _render
    rv = template.render(context)
  File "/run/media/ine/1B6EC43665352BA7/yandex/web_info/flask/env/lib/python3.9/site-packages/jinja2/environment.py", line 1090, in render
    self.environment.handle_exception()
  File "/run/media/ine/1B6EC43665352BA7/yandex/web_info/flask/env/lib/python3.9/site-packages/jinja2/environment.py", line 832, in handle_exception
    reraise(*rewrite_traceback_stack(source=source))
  File "/run/media/ine/1B6EC43665352BA7/yandex/web_info/flask/env/lib/python3.9/site-packages/jinja2/_compat.py", line 28, in reraise
    raise value.with_traceback(tb)
  File "/run/media/ine/1B6EC43665352BA7/yandex/web_info/flask/app/templates/index.html", line 1, in top-level template code
    {% extends "base.html" %}
  File "/run/media/ine/1B6EC43665352BA7/yandex/web_info/flask/app/templates/base.html", line 35, in top-level template code
    {% block content %}{% endblock %}
  File "/run/media/ine/1B6EC43665352BA7/yandex/web_info/flask/app/templates/index.html", line 25, in block "content"
    {% include '_post.html' %}
  File "/run/media/ine/1B6EC43665352BA7/yandex/web_info/flask/app/templates/_post.html", line 5, in top-level template code
    <a href={{url_for('user', username.post.author.username)}}>
  File "/run/media/ine/1B6EC43665352BA7/yandex/web_info/flask/env/lib/python3.9/site-packages/jinja2/environment.py", line 471, in getattr
    return getattr(obj, attribute)
jinja2.exceptions.UndefinedError: 'username' is undefined
2021-02-05 18:43:02,089 ERROR: Exception on /explore [GET] [in /run/media/ine/1B6EC43665352BA7/yandex/web_info/flask/env/lib/python3.9/site-packages/flask/app.py:1891]
Traceback (most recent call last):
  File "/run/media/ine/1B6EC43665352BA7/yandex/web_info/flask/env/lib/python3.9/site-packages/flask/app.py", line 2447, in wsgi_app
    response = self.full_dispatch_request()
  File "/run/media/ine/1B6EC43665352BA7/yandex/web_info/flask/env/lib/python3.9/site-packages/flask/app.py", line 1952, in full_dispatch_request
    rv = self.handle_user_exception(e)
  File "/run/media/ine/1B6EC43665352BA7/yandex/web_info/flask/env/lib/python3.9/site-packages/flask/app.py", line 1821, in handle_user_exception
    reraise(exc_type, exc_value, tb)
  File "/run/media/ine/1B6EC43665352BA7/yandex/web_info/flask/env/lib/python3.9/site-packages/flask/_compat.py", line 39, in reraise
    raise value
  File "/run/media/ine/1B6EC43665352BA7/yandex/web_info/flask/env/lib/python3.9/site-packages/flask/app.py", line 1950, in full_dispatch_request
    rv = self.dispatch_request()
  File "/run/media/ine/1B6EC43665352BA7/yandex/web_info/flask/env/lib/python3.9/site-packages/flask/app.py", line 1936, in dispatch_request
    return self.view_functions[rule.endpoint](**req.view_args)
  File "/run/media/ine/1B6EC43665352BA7/yandex/web_info/flask/env/lib/python3.9/site-packages/flask_login/utils.py", line 272, in decorated_view
    return func(*args, **kwargs)
  File "/run/media/ine/1B6EC43665352BA7/yandex/web_info/flask/app/routes.py", line 187, in explore
    return render_template('index.html', title='Explore', posts=posts)
  File "/run/media/ine/1B6EC43665352BA7/yandex/web_info/flask/env/lib/python3.9/site-packages/flask/templating.py", line 137, in render_template
    return _render(
  File "/run/media/ine/1B6EC43665352BA7/yandex/web_info/flask/env/lib/python3.9/site-packages/flask/templating.py", line 120, in _render
    rv = template.render(context)
  File "/run/media/ine/1B6EC43665352BA7/yandex/web_info/flask/env/lib/python3.9/site-packages/jinja2/environment.py", line 1090, in render
    self.environment.handle_exception()
  File "/run/media/ine/1B6EC43665352BA7/yandex/web_info/flask/env/lib/python3.9/site-packages/jinja2/environment.py", line 832, in handle_exception
    reraise(*rewrite_traceback_stack(source=source))
  File "/run/media/ine/1B6EC43665352BA7/yandex/web_info/flask/env/lib/python3.9/site-packages/jinja2/_compat.py", line 28, in reraise
    raise value.with_traceback(tb)
  File "/run/media/ine/1B6EC43665352BA7/yandex/web_info/flask/app/templates/index.html", line 1, in top-level template code
    {% extends "base.html" %}
  File "/run/media/ine/1B6EC43665352BA7/yandex/web_info/flask/app/templates/base.html", line 35, in top-level template code
    {% block content %}{% endblock %}
  File "/run/media/ine/1B6EC43665352BA7/yandex/web_info/flask/app/templates/index.html", line 25, in block "content"
    {% include '_post.html' %}
  File "/run/media/ine/1B6EC43665352BA7/yandex/web_info/flask/app/templates/_post.html", line 5, in top-level template code
    <a href={{url_for('user', username.post.author.username)}}>
  File "/run/media/ine/1B6EC43665352BA7/yandex/web_info/flask/env/lib/python3.9/site-packages/jinja2/environment.py", line 471, in getattr
    return getattr(obj, attribute)
jinja2.exceptions.UndefinedError: 'username' is undefined
2021-02-05 18:43:37,933 INFO: Microblog startup [in /run/media/ine/1B6EC43665352BA7/yandex/web_info/flask/app/routes.py:150]
2021-02-14 09:57:01,284 INFO: Microblog startup [in /run/media/ine/1B6EC43665352BA7/yandex/web_info/flask/app/routes.py:150]
